Workbook

Sheet FRI report
E2: Final Inspection Report
A4: Client: | D4: Global Tech | I4: Supplier: | L4: Alpha Labs | R4: Client PO#: | U4: PO-XX328
A5: XXX office: | D5: TX | I5: Inspector: | L5: Sam Davis | R5: XXX PO#: | U5: 21668732
A6: PM: | D6: Avery Wilson | I6: Inspection Site: | L6: Greenfield county, Metro city | R6: PO Quantity: | U6: N/A
A7: Project#: | D7: XXBFNO6 | I7: Inspection date: | L7: 46046 | R7: Batch Quantity: | U7: 88907PCS
D8: Date of Manufacture: | L8: 1/18/2026~1/21/2026 | R8: Lot ID: | U8: 9928-539898(1st lot)
A9: Item#: | D9: XX-ABC-68878-C
A10: Description: | D10: Standard Component Assembly with Seal Insert
A12: Sign-off sample: | D12: Yes | G12: Approved drawings | K12: Yes | N12: (Drawing#: | P12: K1VRJNVG | U12: REV: | V12: C | X12: )
A13: Ship mark | D13: Yes | G13: Approved ranges | K13: Yes | U13: Ship to | W13: TBA
A16: Inspection Result: | H16: Accept
U17: Re-inspection: | V17: No | Z17: <<=
B19: ( Comment: | Y19: ) | Z19: <<= | AA19: 1-Single line
AA20: 2-Single line
AA21: 3-Single line
AA22: 4-Double lines
AA23: 4-Double lines
AA24: 5-Double lines
AA25: 5-Double lines
AA26: 6-Double lines
AA27: 6-Double lines
A30: Inspection Result Summary
A32: Check points | D32: Sample size | G32: Comment | J32: Remark
A34: Dimension | D34: 20 | G34: Conformed
A35: Aesthetics | D35: 500 | G35: Conformed
A36: Color | D36: 500 | G36: Conformed
A37: Material | G37: N/A
A38: Decoration | D38: 500 | G38: Conformed
A39: Packaging | G39: N/A
A40: Labeling | G40: N/A
A41: Assortment | G41: N/A
A42: Ship mark | D42: 1 | G42: Conformed
A43: Workmanship | D43: 500 | G43: Conformed
A44: Function | D44: 20 | G44: Conformed
A46: Aesthetic Inspection
A48: Inspection method: | E48: ANSI/ASQ Z1.4 | I48: Sampling plan: | L48: Single sampling normal inspection | T48: Sampling level: | W48: Level 2
A49: Acceptable Quality Level (AQL): | G49: Critical A: | J49: 0 | L49: Critical B: | O49: 0.65 | Q49: Major: | S49: 1.5 | U49: Minor: | W49: 4.0
A50: Sample size: | E50: 500 | K50: No. of carton drawn: | O50: 10
A51: Opened carton No.: | E51: No carton# | Z51: <<=
AB52: 2
...

Sheet Photos 1
E2: Final Inspection Report
A4: Client: | D4: =IF('FRI report'!D4:H4="","",'FRI report'!D4:H4) -> Global Tech | I4: Supplier: | L4: =IF('FRI report'!L4:Q4="","",'FRI report'!L4:Q4) -> Alpha Labs | R4: Client PO#: | U4: =IF('FRI report'!U4:Y4="","",'FRI report'!U4:Y4) -> PO-XX328 | Z4: <- | AA4: All info fill in automatically per FRI report
A5: XXX office: | D5: =IF('FRI report'!D5:H5="","",'FRI report'!D5:H5) -> TX | I5: Inspector: | L5: =IF('FRI report'!L5:Q5="","",'FRI report'!L5:Q5) -> Sam Davis | R5: XXX PO#: | U5: =IF('FRI report'!U5:Y5="","",'FRI report'!U5:Y5) -> 21668732
A6: PM: | D6: =IF('FRI report'!D6:H6="","",'FRI report'!D6:H6) -> Avery Wilson | I6: Inspection Site: | L6: =IF('FRI report'!L6:Q6="","",'FRI report'!L6:Q6) -> Greenfield county, Metro city | R6: PO Quantity: | U6: =IF('FRI report'!U6:Y6="","",'FRI report'!U6:Y6) -> N/A
A7: Project#: | D7: =IF('FRI report'!D7:H7="","",'FRI report'!D7:H7) -> XXBFNO6 | I7: Inspection date: | L7: =IF('FRI report'!L7:Q7="","",'FRI report'!L7:Q7) -> 46046 | R7: Batch Quantity: | U7: =IF('FRI report'!U7:Y7="","",'FRI report'!U7:Y7) -> 88907PCS
R8: Lot ID: | U8: =IF('FRI report'!U8:Y8="","",'FRI report'!U8:Y8) -> 9928-539898(1st lot)
A9: Item#: | D9: =IF('FRI report'!D9:Y9="","",'FRI report'!D9:Y9) -> XX-ABC-68878-C
A10: Description: | D10: =IF('FRI report'!D10:Y10="","",'FRI report'!D10:Y10) -> Standard Component Assembly with Seal Insert
A12: Photos

Sheet Photos 2
E2: Final Inspection Report
A4: Client: | D4: =IF('FRI report'!D4:H4="","",'FRI report'!D4:H4) -> Global Tech | I4: Supplier: | L4: =IF('FRI report'!L4:Q4="","",'FRI report'!L4:Q4) -> Alpha Labs | R4: Client PO#: | U4: =IF('FRI report'!U4:Y4="","",'FRI report'!U4:Y4) -> PO-XX328 | Z4: <- | AA4: All info fill in automatically per FRI report
A5: XXX office: | D5: =IF('FRI report'!D5:H5="","",'FRI report'!D5:H5) -> TX | I5: Inspector: | L5: =IF('FRI report'!L5:Q5="","",'FRI report'!L5:Q5) -> Sam Davis | R5: XXX PO#: | U5: =IF('FRI report'!U5:Y5="","",'FRI report'!U5:Y5) -> 21668732
A6: PM: | D6: =IF('FRI report'!D6:H6="","",'FRI report'!D6:H6) -> Avery Wilson | I6: Inspection Site: | L6: =IF('FRI report'!L6:Q6="","",'FRI report'!L6:Q6) -> Greenfield county, Metro city | R6: PO Quantity: | U6: =IF('FRI report'!U6:Y6="","",'FRI report'!U6:Y6) -> N/A
A7: Project#: | D7: =IF('FRI report'!D7:H7="","",'FRI report'!D7:H7) -> XXBFNO6 | I7: Inspection date: | L7: =IF('FRI report'!L7:Q7="","",'FRI report'!L7:Q7) -> 46046 | R7: Batch Quantity: | U7: =IF('FRI report'!U7:Y7="","",'FRI report'!U7:Y7) -> 88907PCS
R8: Lot ID: | U8: =IF('FRI report'!U8:Y8="","",'FRI report'!U8:Y8) -> 9928-539898(1st lot)
A9: Item#: | D9: =IF('FRI report'!D9:Y9="","",'FRI report'!D9:Y9) -> XX-ABC-68878-C
A10: Description: | D10: =IF('FRI report'!D10:Y10="","",'FRI report'!D10:Y10) -> Standard Component Assembly with Seal Insert
A12: Photos

Sheet Photos 3
E2: Final Inspection Report
A4: Client: | D4: =IF('FRI report'!D4:H4="","",'FRI report'!D4:H4) -> Global Tech | I4: Supplier: | L4: =IF('FRI report'!L4:Q4="","",'FRI report'!L4:Q4) -> Alpha Labs | R4: Client PO#: | U4: =IF('FRI report'!U4:Y4="","",'FRI report'!U4:Y4) -> PO-XX328 | Z4: <- | AA4: All info fill in automatically per FRI report
A5: XXX office: | D5: =IF('FRI report'!D5:H5="","",'FRI report'!D5:H5) -> TX | I5: Inspector: | L5: =IF('FRI report'!L5:Q5="","",'FRI report'!L5:Q5) -> Sam Davis | R5: XXX PO#: | U5: =IF('FRI report'!U5:Y5="","",'FRI report'!U5:Y5) -> 21668732
A6: PM: | D6: =IF('FRI report'!D6:H6="","",'FRI report'!D6:H6) -> Avery Wilson | I6: Inspection Site: | L6: =IF('FRI report'!L6:Q6="","",'FRI report'!L6:Q6) -> Greenfield county, Metro city | R6: PO Quantity: | U6: =IF('FRI report'!U6:Y6="","",'FRI report'!U6:Y6) -> N/A
A7: Project#: | D7: =IF('FRI report'!D7:H7="","",'FRI report'!D7:H7) -> XXBFNO6 | I7: Inspection date: | L7: =IF('FRI report'!L7:Q7="","",'FRI report'!L7:Q7) -> 46046 | R7: Batch Quantity: | U7: =IF('FRI report'!U7:Y7="","",'FRI report'!U7:Y7) -> 88907PCS
R8: Lot ID: | U8: =IF('FRI report'!U8:Y8="","",'FRI report'!U8:Y8) -> 9928-539898(1st lot)
A9: Item#: | D9: =IF('FRI report'!D9:Y9="","",'FRI report'!D9:Y9) -> XX-ABC-68878-C
A10: Description: | D10: =IF('FRI report'!D10:Y10="","",'FRI report'!D10:Y10) -> Standard Component Assembly with Seal Insert
A12: Photos

Sheet Photos 4
E2: Final Inspection Report
A4: Client: | D4: =IF('FRI report'!D4:H4="","",'FRI report'!D4:H4) -> Global Tech | I4: Supplier: | L4: =IF('FRI report'!L4:Q4="","",'FRI report'!L4:Q4) -> Alpha Labs | R4: Client PO#: | U4: =IF('FRI report'!U4:Y4="","",'FRI report'!U4:Y4) -> PO-XX328 | Z4: <- | AA4: All info fill in automatically per FRI report
A5: XXX office: | D5: =IF('FRI report'!D5:H5="","",'FRI report'!D5:H5) -> TX | I5: Inspector: | L5: =IF('FRI report'!L5:Q5="","",'FRI report'!L5:Q5) -> Sam Davis | R5: XXX PO#: | U5: =IF('FRI report'!U5:Y5="","",'FRI report'!U5:Y5) -> 21668732
A6: PM: | D6: =IF('FRI report'!D6:H6="","",'FRI report'!D6:H6) -> Avery Wilson | I6: Inspection Site: | L6: =IF('FRI report'!L6:Q6="","",'FRI report'!L6:Q6) -> Greenfield county, Metro city | R6: PO Quantity: | U6: =IF('FRI report'!U6:Y6="","",'FRI report'!U6:Y6) -> N/A
A7: Project#: | D7: =IF('FRI report'!D7:H7="","",'FRI report'!D7:H7) -> XXBFNO6 | I7: Inspection date: | L7: =IF('FRI report'!L7:Q7="","",'FRI report'!L7:Q7) -> 46046 | R7: Batch Quantity: | U7: =IF('FRI report'!U7:Y7="","",'FRI report'!U7:Y7) -> 88907PCS
R8: Lot ID: | U8: =IF('FRI report'!U8:Y8="","",'FRI report'!U8:Y8) -> 9928-539898(1st lot)
A9: Item#: | D9: =IF('FRI report'!D9:Y9="","",'FRI report'!D9:Y9) -> XX-ABC-68878-C
A10: Description: | D10: =IF('FRI report'!D10:Y10="","",'FRI report'!D10:Y10) -> Standard Component Assembly with Seal Insert
A12: Photos

Sheet Photos 5
E2: Final Inspection Report
A4: Client: | D4: =IF('FRI report'!D4:H4="","",'FRI report'!D4:H4) -> Global Tech | I4: Supplier: | L4: =IF('FRI report'!L4:Q4="","",'FRI report'!L4:Q4) -> Alpha Labs | R4: Client PO#: | U4: =IF('FRI report'!U4:Y4="","",'FRI report'!U4:Y4) -> PO-XX328 | Z4: <- | AA4: All info fill in automatically per FRI report
A5: XXX office: | D5: =IF('FRI report'!D5:H5="","",'FRI report'!D5:H5) -> TX | I5: Inspector: | L5: =IF('FRI report'!L5:Q5="","",'FRI report'!L5:Q5) -> Sam Davis | R5: XXX PO#: | U5: =IF('FRI report'!U5:Y5="","",'FRI report'!U5:Y5) -> 21668732
A6: PM: | D6: =IF('FRI report'!D6:H6="","",'FRI report'!D6:H6) -> Avery Wilson | I6: Inspection Site: | L6: =IF('FRI report'!L6:Q6="","",'FRI report'!L6:Q6) -> Greenfield county, Metro city | R6: PO Quantity: | U6: =IF('FRI report'!U6:Y6="","",'FRI report'!U6:Y6) -> N/A
A7: Project#: | D7: =IF('FRI report'!D7:H7="","",'FRI report'!D7:H7) -> XXBFNO6 | I7: Inspection date: | L7: =IF('FRI report'!L7:Q7="","",'FRI report'!L7:Q7) -> 46046 | R7: Batch Quantity: | U7: =IF('FRI report'!U7:Y7="","",'FRI report'!U7:Y7) -> 88907PCS
R8: Lot ID: | U8: =IF('FRI report'!U8:Y8="","",'FRI report'!U8:Y8) -> 9928-539898(1st lot)
A9: Item#: | D9: =IF('FRI report'!D9:Y9="","",'FRI report'!D9:Y9) -> XX-ABC-68878-C
A10: Description: | D10: =IF('FRI report'!D10:Y10="","",'FRI report'!D10:Y10) -> Standard Component Assembly with Seal Insert
A12: Photos

Sheet Photos 6
E2: Final Inspection Report
A4: Client: | D4: =IF('FRI report'!D4:H4="","",'FRI report'!D4:H4) -> Global Tech | I4: Supplier: | L4: =IF('FRI report'!L4:Q4="","",'FRI report'!L4:Q4) -> Alpha Labs | R4: Client PO#: | U4: =IF('FRI report'!U4:Y4="","",'FRI report'!U4:Y4) -> PO-XX328 | Z4: <- | AA4: All info fill in automatically per FRI report
A5: XXX office: | D5: =IF('FRI report'!D5:H5="","",'FRI report'!D5:H5) -> TX | I5: Inspector: | L5: =IF('FRI report'!L5:Q5="","",'FRI report'!L5:Q5) -> Sam Davis | R5: XXX PO#: | U5: =IF('FRI report'!U5:Y5="","",'FRI report'!U5:Y5) -> 21668732
A6: PM: | D6: =IF('FRI report'!D6:H6="","",'FRI report'!D6:H6) -> Avery Wilson | I6: Inspection Site: | L6: =IF('FRI report'!L6:Q6="","",'FRI report'!L6:Q6) -> Greenfield county, Metro city | R6: PO Quantity: | U6: =IF('FRI report'!U6:Y6="","",'FRI report'!U6:Y6) -> N/A
A7: Project#: | D7: =IF('FRI report'!D7:H7="","",'FRI report'!D7:H7) -> XXBFNO6 | I7: Inspection date: | L7: =IF('FRI report'!L7:Q7="","",'FRI report'!L7:Q7) -> 46046 | R7: Batch Quantity: | U7: =IF('FRI report'!U7:Y7="","",'FRI report'!U7:Y7) -> 88907PCS
R8: Lot ID: | U8: =IF('FRI report'!U8:Y8="","",'FRI report'!U8:Y8) -> 9928-539898(1st lot)
A9: Item#: | D9: =IF('FRI report'!D9:Y9="","",'FRI report'!D9:Y9) -> XX-ABC-68878-C
A10: Description: | D10: =IF('FRI report'!D10:Y10="","",'FRI report'!D10:Y10) -> Standard Component Assembly with Seal Insert
A12: Photos

Sheet db
A1: defects found No | B1: OD stem "D" | C1: disc/jar
A2: air bubble | B2: OD "S" stem | C2: ?times
A3: embedded bottle dot in black | B3: "Wing"thickness | C3: （?oz.in) smoothly
A4: material dot black in | B4: ( * | C4: ?kgf
A5: was cup top the up rotated to not | B5: (BOTTOM)ID | C5: spatula/cap/jar
A6: mark cutting | B6: (Result: | C6: Cap/Wiper/Bottle
A7: damaged | B7: (UP)ID | C7: cap Cap/Base/Disc/Inner
A8: deformation | B8: OD A-shell | C8: cap/sifter/jar
A9: mark dent | B9: Acceptable Quality Level (AQL): | C9: Sifter&Jar&Cap
A10: dirt mark | B10: L Acetate | C10: palette With AL
A11: mark dirt | B11: Acetate thickness | C11: normal use
A12: be cleaned) mark(can dirt | B12: W Acetate | C12: correct be and scanned can
... A54: wrinkled mark | B54: Toatal H assembly | C54: UC with
B55: total gap Assembly | C55: flute Liner with
B56: total assembly H | C56: ?g
B57: Total H assembly | C57: Cap/Bottle/Wiper
B58: H Assembly total | C58: lbf.in ?
B59: Assembly H Total | C59: Cap/Sifter/Jar
B60: (with Assembly base,sifter) total H | C60: torque application mini of half
B61: bottle,pump) Assembly total (With H | C61: >?kgf.cm
B62: H (with bottle) total Assembly | C62: PPS:?g
B63: total (with H Assembly cap, sifter) | C63: pump/bottle
B64: Assembly total cap) (with H | C64: coaster/bottle
B65: (with total logo) H Assembly | C65: rollers finger,spin a with the
B66: H Assembly Pot) total (with | C66: sifter/glass jar
... B131: E Bottle | C131: crease per
B132: bottle H
B133: H Bottle
B134: H BOTTLE
B135: Bottle H (without neck)
B136: Bottle shoulder H with
B137: without Height Bottle neck
B138: I Bottle
B139: bottle ID
B140: ID Bottle
B141: inner Bottle depth
B142: depth Inner Bottle
B143: bottle L
... B906: Zhu
